Traceback (most recent call last):
  File "C:\Users\Admin\AppData\Local\Programs\Python\Python313\Lib\site-packages\jupyter_cache\executors\utils.py", line 58, in single_nb_execution
    executenb(
    ~~~~~~~~~^
        nb,
        ^^^
    ...<4 lines>...
        **kwargs,
        ^^^^^^^^^
    )
    ^
  File "C:\Users\Admin\AppData\Local\Programs\Python\Python313\Lib\site-packages\nbclient\client.py", line 1319, in execute
    return NotebookClient(nb=nb, resources=resources, km=km, **kwargs).execute()
           ~~~~~~~~~~~~~~~~~~~~~~~~~~~~~~~~~~~~~~~~~~~~~~~~~~~~~~~~~~~~~~~~~~~^^
  File "C:\Users\Admin\AppData\Roaming\Python\Python313\site-packages\jupyter_core\utils\__init__.py", line 165, in wrapped
    return loop.run_until_complete(inner)
           ~~~~~~~~~~~~~~~~~~~~~~~^^^^^^^
  File "C:\Users\Admin\AppData\Local\Programs\Python\Python313\Lib\asyncio\base_events.py", line 719, in run_until_complete
    return future.result()
           ~~~~~~~~~~~~~^^
  File "C:\Users\Admin\AppData\Local\Programs\Python\Python313\Lib\site-packages\nbclient\client.py", line 709, in async_execute
    await self.async_execute_cell(
        cell, index, execution_count=self.code_cells_executed + 1
    )
  File "C:\Users\Admin\AppData\Local\Programs\Python\Python313\Lib\site-packages\nbclient\client.py", line 1062, in async_execute_cell
    await self._check_raise_for_error(cell, cell_index, exec_reply)
  File "C:\Users\Admin\AppData\Local\Programs\Python\Python313\Lib\site-packages\nbclient\client.py", line 918, in _check_raise_for_error
    raise CellExecutionError.from_cell_and_msg(cell, exec_reply_content)
nbclient.exceptions.CellExecutionError: An error occurred while executing the following cell:
------------------
my_df = pl.DataFrame({
    'id' : [1,2,3],
    'var1' : [5,4,2],
    'var2' : ['a', 'a', 'b'],
    'var3' : ['x', 'y', 'z']
})
------------------


[31m---------------------------------------------------------------------------[39m
[31mNameError[39m                                 Traceback (most recent call last)
[36mCell[39m[36m [39m[32mIn[93][39m[32m, line 1[39m
[32m----> [39m[32m1[39m my_df = [43mpl[49m.DataFrame({
[32m      2[39m     [33m'[39m[33mid[39m[33m'[39m : [[32m1[39m,[32m2[39m,[32m3[39m],
[32m      3[39m     [33m'[39m[33mvar1[39m[33m'[39m : [[32m5[39m,[32m4[39m,[32m2[39m],
[32m      4[39m     [33m'[39m[33mvar2[39m[33m'[39m : [[33m'[39m[33ma[39m[33m'[39m, [33m'[39m[33ma[39m[33m'[39m, [33m'[39m[33mb[39m[33m'[39m],
[32m      5[39m     [33m'[39m[33mvar3[39m[33m'[39m : [[33m'[39m[33mx[39m[33m'[39m, [33m'[39m[33my[39m[33m'[39m, [33m'[39m[33mz[39m[33m'[39m]
[32m      6[39m })

[31mNameError[39m: name 'pl' is not defined

