Traceback (most recent call last):
  File "C:\Users\Admin\AppData\Local\Programs\Python\Python313\Lib\site-packages\jupyter_cache\executors\utils.py", line 58, in single_nb_execution
    executenb(
    ~~~~~~~~~^
        nb,
        ^^^
    ...<4 lines>...
        **kwargs,
        ^^^^^^^^^
    )
    ^
  File "C:\Users\Admin\AppData\Local\Programs\Python\Python313\Lib\site-packages\nbclient\client.py", line 1319, in execute
    return NotebookClient(nb=nb, resources=resources, km=km, **kwargs).execute()
           ~~~~~~~~~~~~~~~~~~~~~~~~~~~~~~~~~~~~~~~~~~~~~~~~~~~~~~~~~~~~~~~~~~~^^
  File "C:\Users\Admin\AppData\Roaming\Python\Python313\site-packages\jupyter_core\utils\__init__.py", line 165, in wrapped
    return loop.run_until_complete(inner)
           ~~~~~~~~~~~~~~~~~~~~~~~^^^^^^^
  File "C:\Users\Admin\AppData\Local\Programs\Python\Python313\Lib\asyncio\base_events.py", line 719, in run_until_complete
    return future.result()
           ~~~~~~~~~~~~~^^
  File "C:\Users\Admin\AppData\Local\Programs\Python\Python313\Lib\site-packages\nbclient\client.py", line 709, in async_execute
    await self.async_execute_cell(
        cell, index, execution_count=self.code_cells_executed + 1
    )
  File "C:\Users\Admin\AppData\Local\Programs\Python\Python313\Lib\site-packages\nbclient\client.py", line 1062, in async_execute_cell
    await self._check_raise_for_error(cell, cell_index, exec_reply)
  File "C:\Users\Admin\AppData\Local\Programs\Python\Python313\Lib\site-packages\nbclient\client.py", line 918, in _check_raise_for_error
    raise CellExecutionError.from_cell_and_msg(cell, exec_reply_content)
nbclient.exceptions.CellExecutionError: An error occurred while executing the following cell:
------------------
import matplotlib.pyplot as plt
import numpy as np
plt.style.use('seaborn')
%matplotlib inline
rng = np.random.RandomState(50)
x = 10 * rng.rand(50)
y = 2 * x - 1 + rng.randn(50)
plt.scatter(x, y)
------------------


[31m---------------------------------------------------------------------------[39m
[31mFileNotFoundError[39m                         Traceback (most recent call last)
[36mFile [39m[32m~\AppData\Local\Programs\Python\Python313\Lib\site-packages\matplotlib\style\core.py:129[39m, in [36muse[39m[34m(style)[39m
[32m    128[39m [38;5;28;01mtry[39;00m:
[32m--> [39m[32m129[39m     style = [43m_rc_params_in_file[49m[43m([49m[43mstyle[49m[43m)[49m
[32m    130[39m [38;5;28;01mexcept[39;00m [38;5;167;01mOSError[39;00m [38;5;28;01mas[39;00m err:

[36mFile [39m[32m~\AppData\Local\Programs\Python\Python313\Lib\site-packages\matplotlib\__init__.py:903[39m, in [36m_rc_params_in_file[39m[34m(fname, transform, fail_on_error)[39m
[32m    902[39m rc_temp = {}
[32m--> [39m[32m903[39m [43m[49m[38;5;28;43;01mwith[39;49;00m[43m [49m[43m_open_file_or_url[49m[43m([49m[43mfname[49m[43m)[49m[43m [49m[38;5;28;43;01mas[39;49;00m[43m [49m[43mfd[49m[43m:[49m
[32m    904[39m [43m    [49m[38;5;28;43;01mtry[39;49;00m[43m:[49m

[36mFile [39m[32m~\AppData\Local\Programs\Python\Python313\Lib\contextlib.py:141[39m, in [36m_GeneratorContextManager.__enter__[39m[34m(self)[39m
[32m    140[39m [38;5;28;01mtry[39;00m:
[32m--> [39m[32m141[39m     [38;5;28;01mreturn[39;00m [38;5;28;43mnext[39;49m[43m([49m[38;5;28;43mself[39;49m[43m.[49m[43mgen[49m[43m)[49m
[32m    142[39m [38;5;28;01mexcept[39;00m [38;5;167;01mStopIteration[39;00m:

[36mFile [39m[32m~\AppData\Local\Programs\Python\Python313\Lib\site-packages\matplotlib\__init__.py:880[39m, in [36m_open_file_or_url[39m[34m(fname)[39m
[32m    879[39m fname = os.path.expanduser(fname)
[32m--> [39m[32m880[39m [38;5;28;01mwith[39;00m [38;5;28;43mopen[39;49m[43m([49m[43mfname[49m[43m,[49m[43m [49m[43mencoding[49m[43m=[49m[33;43m'[39;49m[33;43mutf-8[39;49m[33;43m'[39;49m[43m)[49m [38;5;28;01mas[39;00m f:
[32m    881[39m     [38;5;28;01myield[39;00m f

[31mFileNotFoundError[39m: [Errno 2] No such file or directory: 'seaborn'

The above exception was the direct cause of the following exception:

[31mOSError[39m                                   Traceback (most recent call last)
[36mCell[39m[36m [39m[32mIn[1][39m[32m, line 3[39m
[32m      1[39m [38;5;28;01mimport[39;00m[38;5;250m [39m[34;01mmatplotlib[39;00m[34;01m.[39;00m[34;01mpyplot[39;00m[38;5;250m [39m[38;5;28;01mas[39;00m[38;5;250m [39m[34;01mplt[39;00m
[32m      2[39m [38;5;28;01mimport[39;00m[38;5;250m [39m[34;01mnumpy[39;00m[38;5;250m [39m[38;5;28;01mas[39;00m[38;5;250m [39m[34;01mnp[39;00m
[32m----> [39m[32m3[39m [43mplt[49m[43m.[49m[43mstyle[49m[43m.[49m[43muse[49m[43m([49m[33;43m'[39;49m[33;43mseaborn[39;49m[33;43m'[39;49m[43m)[49m
[32m      4[39m get_ipython().run_line_magic([33m'[39m[33mmatplotlib[39m[33m'[39m, [33m'[39m[33minline[39m[33m'[39m)
[32m      5[39m rng = np.random.RandomState([32m50[39m)

[36mFile [39m[32m~\AppData\Local\Programs\Python\Python313\Lib\site-packages\matplotlib\style\core.py:131[39m, in [36muse[39m[34m(style)[39m
[32m    129[39m         style = _rc_params_in_file(style)
[32m    130[39m     [38;5;28;01mexcept[39;00m [38;5;167;01mOSError[39;00m [38;5;28;01mas[39;00m err:
[32m--> [39m[32m131[39m         [38;5;28;01mraise[39;00m [38;5;167;01mOSError[39;00m(
[32m    132[39m             [33mf[39m[33m"[39m[38;5;132;01m{[39;00mstyle[38;5;132;01m!r}[39;00m[33m is not a valid package style, path of style [39m[33m"[39m
[32m    133[39m             [33mf[39m[33m"[39m[33mfile, URL of style file, or library style name (library [39m[33m"[39m
[32m    134[39m             [33mf[39m[33m"[39m[33mstyles are listed in `style.available`)[39m[33m"[39m) [38;5;28;01mfrom[39;00m[38;5;250m [39m[34;01merr[39;00m
[32m    135[39m filtered = {}
[32m    136[39m [38;5;28;01mfor[39;00m k [38;5;129;01min[39;00m style:  [38;5;66;03m# don't trigger RcParams.__getitem__('backend')[39;00m

[31mOSError[39m: 'seaborn' is not a valid package style, path of style file, URL of style file, or library style name (library styles are listed in `style.available`)

