Traceback (most recent call last):
  File "C:\Users\Admin\AppData\Local\Programs\Python\Python313\Lib\site-packages\jupyter_cache\executors\utils.py", line 58, in single_nb_execution
    executenb(
    ~~~~~~~~~^
        nb,
        ^^^
    ...<4 lines>...
        **kwargs,
        ^^^^^^^^^
    )
    ^
  File "C:\Users\Admin\AppData\Local\Programs\Python\Python313\Lib\site-packages\nbclient\client.py", line 1319, in execute
    return NotebookClient(nb=nb, resources=resources, km=km, **kwargs).execute()
           ~~~~~~~~~~~~~~~~~~~~~~~~~~~~~~~~~~~~~~~~~~~~~~~~~~~~~~~~~~~~~~~~~~~^^
  File "C:\Users\Admin\AppData\Roaming\Python\Python313\site-packages\jupyter_core\utils\__init__.py", line 165, in wrapped
    return loop.run_until_complete(inner)
           ~~~~~~~~~~~~~~~~~~~~~~~^^^^^^^
  File "C:\Users\Admin\AppData\Local\Programs\Python\Python313\Lib\asyncio\base_events.py", line 719, in run_until_complete
    return future.result()
           ~~~~~~~~~~~~~^^
  File "C:\Users\Admin\AppData\Local\Programs\Python\Python313\Lib\site-packages\nbclient\client.py", line 709, in async_execute
    await self.async_execute_cell(
        cell, index, execution_count=self.code_cells_executed + 1
    )
  File "C:\Users\Admin\AppData\Local\Programs\Python\Python313\Lib\site-packages\nbclient\client.py", line 1062, in async_execute_cell
    await self._check_raise_for_error(cell, cell_index, exec_reply)
  File "C:\Users\Admin\AppData\Local\Programs\Python\Python313\Lib\site-packages\nbclient\client.py", line 918, in _check_raise_for_error
    raise CellExecutionError.from_cell_and_msg(cell, exec_reply_content)
nbclient.exceptions.CellExecutionError: An error occurred while executing the following cell:
------------------
import numpy as np
from tensorflow import keras
int_sequence = np.arange(10)
dummy_dataset = keras.utils.timeseries_dataset_from_array(
    data=int_sequence[:-3],
    targets=int_sequence[3:],
    sequence_length=3,
    batch_size=2,
)
for inputs, targets in dummy_dataset:
    for i in range(inputs.shape[0]):
        print([int(x) for x in inputs[i]], int(targets[i]))
------------------


[31m---------------------------------------------------------------------------[39m
[31mModuleNotFoundError[39m                       Traceback (most recent call last)
[36mCell[39m[36m [39m[32mIn[1][39m[32m, line 2[39m
[32m      1[39m [38;5;28;01mimport[39;00m[38;5;250m [39m[34;01mnumpy[39;00m[38;5;250m [39m[38;5;28;01mas[39;00m[38;5;250m [39m[34;01mnp[39;00m
[32m----> [39m[32m2[39m [38;5;28;01mfrom[39;00m[38;5;250m [39m[34;01mtensorflow[39;00m[38;5;250m [39m[38;5;28;01mimport[39;00m keras
[32m      3[39m int_sequence = np.arange([32m10[39m)
[32m      4[39m dummy_dataset = keras.utils.timeseries_dataset_from_array(
[32m      5[39m     data=int_sequence[:-[32m3[39m],
[32m      6[39m     targets=int_sequence[[32m3[39m:],
[32m      7[39m     sequence_length=[32m3[39m,
[32m      8[39m     batch_size=[32m2[39m,
[32m      9[39m )

[31mModuleNotFoundError[39m: No module named 'tensorflow'

